<robot name="mechanum_car">
  <link name="mechanum_chasis">
    <visual>
      <origin xyz="0 0.1 0" rpy="0 0 0" />
      <geometry>
        <box size="0.15 0.35 0.08"/>
      </geometry>
    </visual>
    <collision>
      <origin xyz="0 0.1 0" rpy="0 0 0" />
      <geometry>
        <box size="0.15 0.35 0.08"/>
      </geometry>
    </collision>
  </link>

  <link name="front_left_wheel">
    <visual>
      <geometry>
        <cylinder radius="0.07" length="0.05"/>
      </geometry>
    </visual>
    <collision>
      <geometry>
        <cylinder radius="0.07" length="0.05"/>
      </geometry>
    </collision>
  </link>

  <joint name="front_left_hinge" type="continuous">
    <parent link="mechanum_chasis"/>
    <child link="front_left_wheel"/>
    <axis xyz="0.0 0.0 1.0"/>
    <origin xyz="0.1 0.1 -0.03" rpy="0 -1.5708 0" />
  </joint>
</robot>