<?xml version="1.0" ?>
<robot name="mechanum_car">
  <link name="world"/>
  <link name="mechanum_chasis">
    <visual>
      <geometry>
        <box size="0.15 0.35 0.08"/>
      </geometry>
    </visual>
    <collision>
      <origin xyz="0 0.1 0" rpy="0 0 0" />
      <geometry>
        <box size="0.15 0.35 0.08"/>
      </geometry>
    </collision>
    <inertial>
      <mass value="100"/>
      <inertia ixx="1.0" ixy="0.0" ixz="0.0" iyy="1.0" iyz="0.0" izz="1.0"/>
    </inertial>
  </link>
  <joint name="world_to_base" type="fixed">
    <origin rpy="0 0 0" xyz="0 0 0.1"/>
    <parent link="world"/>
    <child link="mechanum_chasis"/>
  </joint>

  <link name="front_left_wheel">
    <visual>
      <geometry>
        <cylinder radius="0.07" length="0.05"/>
      </geometry>
    </visual>
    <collision>
      <geometry>
        <cylinder radius="0.07" length="0.05"/>
      </geometry>
    </collision>
    <inertial>
      <mass value="100"/>
      <inertia ixx="1.0" ixy="0.0" ixz="0.0" iyy="1.0" iyz="0.0" izz="1.0"/>
    </inertial>
  </link>
  <joint name="front_left_hinge" type="continuous">
    <parent link="mechanum_chasis"/>
    <child link="front_left_wheel"/>
    <axis xyz="0.0 0.0 1.0"/>
    <origin xyz="0.1 0.1 -0.03" rpy="0 -1.5708 0" />
  </joint>

    <link name="front_right_wheel">
    <visual>
      <geometry>
        <cylinder radius="0.07" length="0.05"/>
      </geometry>
    </visual>
    <collision>
      <geometry>
        <cylinder radius="0.07" length="0.05"/>
      </geometry>
    </collision>
    <inertial>
      <mass value="100"/>
      <inertia ixx="1.0" ixy="0.0" ixz="0.0" iyy="1.0" iyz="0.0" izz="1.0"/>
    </inertial>
  </link>
  <joint name="front_right_hinge" type="continuous">
    <parent link="mechanum_chasis"/>
    <child link="front_right_wheel"/>
    <axis xyz="0.0 0.0 1.0"/>
    <origin xyz="-0.1 0.1 -0.03" rpy="0 -1.5708 0" />
  </joint>

    <link name="back_left_wheel">
    <visual>
      <geometry>
        <cylinder radius="0.07" length="0.05"/>
      </geometry>
    </visual>
    <collision>
      <geometry>
        <cylinder radius="0.07" length="0.05"/>
      </geometry>
    </collision>
    <inertial>
      <mass value="100"/>
      <inertia ixx="1.0" ixy="0.0" ixz="0.0" iyy="1.0" iyz="0.0" izz="1.0"/>
    </inertial>
  </link>
  <joint name="back_left_hinge" type="continuous">
    <parent link="mechanum_chasis"/>
    <child link="back_left_wheel"/>
    <axis xyz="0.0 0.0 1.0"/>
    <origin xyz="0.1 -0.1 -0.03" rpy="0 -1.5708 0" />
  </joint>

    <link name="back_right_wheel">
    <visual>
      <geometry>
        <cylinder radius="0.07" length="0.05"/>
      </geometry>
    </visual>
    <collision>
      <geometry>
        <cylinder radius="0.07" length="0.05"/>
      </geometry>
    </collision>
    <inertial>
      <mass value="100"/>
      <inertia ixx="1.0" ixy="0.0" ixz="0.0" iyy="1.0" iyz="0.0" izz="1.0"/>
    </inertial>
  </link>
  <joint name="back_right_hinge" type="continuous">
    <parent link="mechanum_chasis"/>
    <child link="back_right_wheel"/>
    <axis xyz="0.0 0.0 1.0"/>
    <origin xyz="-0.1 -0.1 -0.03" rpy="0 -1.5708 0" />
  </joint>
</robot>