<?xml version="1.0"?>
<sdf version="1.7">
  <model name="mecanum_car">
    <link name="body">
      <pose>0 0 0.1 0 0 0</pose>
      <visual name="visual">
        <geometry>
          <box>
            <size>0.15 0.35 0.08</size>
          </box>
        </geometry>
      </visual>
      <collision name="collision">
        <geometry>
          <box>
            <size>0.15 0.35 0.08</size>
          </box>
        </geometry>
      </collision>
      <surface>
          <friction>
            <ode>
              <mu>0</mu>
              <mu2>0</mu2>
              <slip1>1.0</slip1>
              <slip2>1.0</slip2>
            </ode>
          </friction>
        </surface>
    </link>

    <link name="front_left_wheel">
      <pose relative_to="body">0.1 0.1 -0.03 0 -1.5708 0</pose>
      <visual name="visual">
        <geometry>
          <cylinder>
            <radius>0.07</radius>
            <length>0.05</length>
          </cylinder>
        </geometry>
      </visual>
      <collision name="collision">
        <geometry>
          <cylinder>
            <radius>0.07</radius>
            <length>0.05</length>
          </cylinder>
        </geometry>
      </collision>
    </link>
    <joint name="front_left_hinge" type="revolute">
      <parent>body</parent>
      <child>front_left_wheel</child>
      <axis>
        <xyz>0 0 1</xyz>
      </axis>
    </joint>

    <link name="front_right_wheel">
      <pose relative_to="body">-0.1 0.1 -0.03 0 -1.5708 0</pose>
      <visual name="visual">
        <geometry>
          <cylinder>
            <radius>0.07</radius>
            <length>0.05</length>
          </cylinder>
        </geometry>
      </visual>
      <collision name="collision">
        <geometry>
          <cylinder>
            <radius>0.07</radius>
            <length>0.05</length>
          </cylinder>
        </geometry>
      </collision>
    </link>
    <joint name="front_right_hinge" type="revolute">
      <parent>body</parent>
      <child>front_right_wheel</child>
      <axis>
        <xyz>0 0 1</xyz>
      </axis>
    </joint>

    <link name="back_right_wheel">
      <pose relative_to="body">-0.1 -0.1 -0.03 0 -1.5708 0</pose>
      <visual name="visual">
        <geometry>
          <cylinder>
            <radius>0.07</radius>
            <length>0.05</length>
          </cylinder>
        </geometry>
      </visual>
      <collision name="collision">
        <geometry>
          <cylinder>
            <radius>0.07</radius>
            <length>0.05</length>
          </cylinder>
        </geometry>
      </collision>
    </link>
    <joint name="back_right_hinge" type="revolute">
      <parent>body</parent>
      <child>back_right_wheel</child>
      <axis>
        <xyz>0 0 1</xyz>
      </axis>
    </joint>

    <link name="back_left_wheel">
      <pose relative_to="body">0.1 -0.1 -0.03 0 -1.5708 0</pose>
      <visual name="visual">
        <geometry>
          <cylinder>
            <radius>0.07</radius>
            <length>0.05</length>
          </cylinder>
        </geometry>
      </visual>
      <collision name="collision">
        <geometry>
          <cylinder>
            <radius>0.07</radius>
            <length>0.05</length>
          </cylinder>
        </geometry>
      </collision>
    </link>
    <joint name="back_left_hinge" type="revolute">
      <parent>body</parent>
      <child>back_left_wheel</child>
      <axis>
        <xyz>0 0 1</xyz>
      </axis>
    </joint>

    <plugin name="libtest_control_plugin" filename="libtest_control_plugin.so">
      <velocity>0</velocity>
    </plugin>
  </model>
</sdf>
